2025-05-21T12:47:36+00:00 liaserver2 python3[1190]: /usr/lib/python3/dist-packages/uaclient/apt_news.py:207: Warning: W:Download is performed unsandboxed as root as file '/run/ubuntu-advantage/aptnews.json' couldn't be accessed by user '_apt'. - pkgAcquire::Run (13: Permission denied)
2025-05-21T12:47:36+00:00 liaserver2 python3[1190]:   acq.run()
2025-05-21T12:48:28+00:00 liaserver2 python3[1191]: ["2025-05-21T12:48:28.607", "ERROR", "ubuntupro.http", "_readurl_urllib", 171, "[Errno 101] Network is unreachable", {"exc_info": "Traceback (most recent call last):\n  File \"/usr/lib/python3.12/urllib/request.py\", line 1344, in do_open\n    h.request(req.get_method(), req.selector, req.data, headers,\n  File \"/usr/lib/python3.12/http/client.py\", line 1336, in request\n    self._send_request(method, url, body, headers, encode_chunked)\n  File \"/usr/lib/python3.12/http/client.py\", line 1382, in _send_request\n    self.endheaders(body, encode_chunked=encode_chunked)\n  File \"/usr/lib/python3.12/http/client.py\", line 1331, in endheaders\n    self._send_output(message_body, encode_chunked=encode_chunked)\n  File \"/usr/lib/python3.12/http/client.py\", line 1091, in _send_output\n    self.send(msg)\n  File \"/usr/lib/python3.12/http/client.py\", line 1035, in send\n    self.connect()\n  File \"/usr/lib/python3.12/http/client.py\", line 1470, in connect\n    super().connect()\n  File \"/usr/lib/python3.12/http/client.py\", line 1001, in connect\n    self.sock = self._create_connection(\n                ^^^^^^^^^^^^^^^^^^^^^^^^\n  File \"/usr/lib/python3.12/socket.py\", line 852, in create_connection\n    raise exceptions[0]\n  File \"/usr/lib/python3.12/socket.py\", line 837, in create_connection\n    sock.connect(sa)\nOSError: [Errno 101] Network is unreachable\n\nDuring handling of the above exception, another exception occurred:\n\nTraceback (most recent call last):\n  File \"/usr/lib/python3/dist-packages/uaclient/http/__init__.py\", line 167, in _readurl_urllib\n    resp = request.urlopen(req, timeout=timeout)  # nosec B310\n           ^^^^^^^^^^^^^^^^^^^^^^^^^^^^^^^^^^^^^\n  File \"/usr/lib/python3.12/urllib/request.py\", line 215, in urlopen\n    return opener.open(url, data, timeout)\n           ^^^^^^^^^^^^^^^^^^^^^^^^^^^^^^^\n  File \"/usr/lib/python3.12/urllib/request.py\", line 515, in open\n    response = self._open(req, data)\n               ^^^^^^^^^^^^^^^^^^^^^\n  File \"/usr/lib/python3.12/urllib/request.py\", line 532, in _open\n    result = self._call_chain(self.handle_open, protocol, protocol +\n             ^^^^^^^^^^^^^^^^^^^^^^^^^^^^^^^^^^^^^^^^^^^^^^^^^^^^^^^\n  File \"/usr/lib/python3.12/urllib/request.py\", line 492, in _call_chain\n    result = func(*args)\n             ^^^^^^^^^^^\n  File \"/usr/lib/python3.12/urllib/request.py\", line 1392, in https_open\n    return self.do_open(http.client.HTTPSConnection, req,\n           ^^^^^^^^^^^^^^^^^^^^^^^^^^^^^^^^^^^^^^^^^^^^^^\n  File \"/usr/lib/python3.12/urllib/request.py\", line 1347, in do_open\n    raise URLError(err)\nurllib.error.URLError: <urlopen error [Errno 101] Network is unreachable>"}]
2025-05-21T12:48:28+00:00 liaserver2 python3[1191]: ["2025-05-21T12:48:28.623", "ERROR", "ubuntupro.lib.esm_cache", "main", 17, "Error updating the cache: Failed to connect to https://contracts.canonical.com/v1/resources?architecture=amd64&kernel=6.8.0-53-generic&series=noble&virt=oracle\n[Errno 101] Network is unreachable\n", {}]
2025-05-21T12:51:46+00:00 liaserver2 python3[1255]: /usr/lib/python3/dist-packages/uaclient/apt_news.py:207: Warning: W:Download is performed unsandboxed as root as file '/run/ubuntu-advantage/aptnews.json' couldn't be accessed by user '_apt'. - pkgAcquire::Run (13: Permission denied)
2025-05-21T12:51:46+00:00 liaserver2 python3[1255]:   acq.run()
2025-05-21T12:52:39+00:00 liaserver2 python3[1258]: ["2025-05-21T12:52:39.172", "ERROR", "ubuntupro.http", "_readurl_urllib", 171, "[Errno 111] Connection refused", {"exc_info": "Traceback (most recent call last):\n  File \"/usr/lib/python3.12/urllib/request.py\", line 1344, in do_open\n    h.request(req.get_method(), req.selector, req.data, headers,\n  File \"/usr/lib/python3.12/http/client.py\", line 1336, in request\n    self._send_request(method, url, body, headers, encode_chunked)\n  File \"/usr/lib/python3.12/http/client.py\", line 1382, in _send_request\n    self.endheaders(body, encode_chunked=encode_chunked)\n  File \"/usr/lib/python3.12/http/client.py\", line 1331, in endheaders\n    self._send_output(message_body, encode_chunked=encode_chunked)\n  File \"/usr/lib/python3.12/http/client.py\", line 1091, in _send_output\n    self.send(msg)\n  File \"/usr/lib/python3.12/http/client.py\", line 1035, in send\n    self.connect()\n  File \"/usr/lib/python3.12/http/client.py\", line 1470, in connect\n    super().connect()\n  File \"/usr/lib/python3.12/http/client.py\", line 1001, in connect\n    self.sock = self._create_connection(\n                ^^^^^^^^^^^^^^^^^^^^^^^^\n  File \"/usr/lib/python3.12/socket.py\", line 852, in create_connection\n    raise exceptions[0]\n  File \"/usr/lib/python3.12/socket.py\", line 837, in create_connection\n    sock.connect(sa)\nConnectionRefusedError: [Errno 111] Connection refused\n\nDuring handling of the above exception, another exception occurred:\n\nTraceback (most recent call last):\n  File \"/usr/lib/python3/dist-packages/uaclient/http/__init__.py\", line 167, in _readurl_urllib\n    resp = request.urlopen(req, timeout=timeout)  # nosec B310\n           ^^^^^^^^^^^^^^^^^^^^^^^^^^^^^^^^^^^^^\n  File \"/usr/lib/python3.12/urllib/request.py\", line 215, in urlopen\n    return opener.open(url, data, timeout)\n           ^^^^^^^^^^^^^^^^^^^^^^^^^^^^^^^\n  File \"/usr/lib/python3.12/urllib/request.py\", line 515, in open\n    response = self._open(req, data)\n               ^^^^^^^^^^^^^^^^^^^^^\n  File \"/usr/lib/python3.12/urllib/request.py\", line 532, in _open\n    result = self._call_chain(self.handle_open, protocol, protocol +\n             ^^^^^^^^^^^^^^^^^^^^^^^^^^^^^^^^^^^^^^^^^^^^^^^^^^^^^^^\n  File \"/usr/lib/python3.12/urllib/request.py\", line 492, in _call_chain\n    result = func(*args)\n             ^^^^^^^^^^^\n  File \"/usr/lib/python3.12/urllib/request.py\", line 1392, in https_open\n    return self.do_open(http.client.HTTPSConnection, req,\n           ^^^^^^^^^^^^^^^^^^^^^^^^^^^^^^^^^^^^^^^^^^^^^^\n  File \"/usr/lib/python3.12/urllib/request.py\", line 1347, in do_open\n    raise URLError(err)\nurllib.error.URLError: <urlopen error [Errno 111] Connection refused>"}]
2025-05-21T12:52:39+00:00 liaserver2 python3[1258]: ["2025-05-21T12:52:39.180", "ERROR", "ubuntupro.lib.esm_cache", "main", 17, "Error updating the cache: Failed to connect to https://contracts.canonical.com/v1/resources?architecture=amd64&kernel=6.8.0-53-generic&series=noble&virt=oracle\n[Errno 111] Connection refused\n", {}]
2025-05-21T13:03:30+00:00 liaserver2 python3[1482]: /usr/lib/python3/dist-packages/uaclient/apt_news.py:207: Warning: W:Download is performed unsandboxed as root as file '/run/ubuntu-advantage/aptnews.json' couldn't be accessed by user '_apt'. - pkgAcquire::Run (13: Permission denied)
2025-05-21T13:03:30+00:00 liaserver2 python3[1482]:   acq.run()
2025-05-21T13:03:51+00:00 liaserver2 python3[1483]: ["2025-05-21T13:03:51.088", "ERROR", "ubuntupro.http", "_readurl_urllib", 171, "[Errno 111] Connection refused", {"exc_info": "Traceback (most recent call last):\n  File \"/usr/lib/python3.12/urllib/request.py\", line 1344, in do_open\n    h.request(req.get_method(), req.selector, req.data, headers,\n  File \"/usr/lib/python3.12/http/client.py\", line 1336, in request\n    self._send_request(method, url, body, headers, encode_chunked)\n  File \"/usr/lib/python3.12/http/client.py\", line 1382, in _send_request\n    self.endheaders(body, encode_chunked=encode_chunked)\n  File \"/usr/lib/python3.12/http/client.py\", line 1331, in endheaders\n    self._send_output(message_body, encode_chunked=encode_chunked)\n  File \"/usr/lib/python3.12/http/client.py\", line 1091, in _send_output\n    self.send(msg)\n  File \"/usr/lib/python3.12/http/client.py\", line 1035, in send\n    self.connect()\n  File \"/usr/lib/python3.12/http/client.py\", line 1470, in connect\n    super().connect()\n  File \"/usr/lib/python3.12/http/client.py\", line 1001, in connect\n    self.sock = self._create_connection(\n                ^^^^^^^^^^^^^^^^^^^^^^^^\n  File \"/usr/lib/python3.12/socket.py\", line 852, in create_connection\n    raise exceptions[0]\n  File \"/usr/lib/python3.12/socket.py\", line 837, in create_connection\n    sock.connect(sa)\nConnectionRefusedError: [Errno 111] Connection refused\n\nDuring handling of the above exception, another exception occurred:\n\nTraceback (most recent call last):\n  File \"/usr/lib/python3/dist-packages/uaclient/http/__init__.py\", line 167, in _readurl_urllib\n    resp = request.urlopen(req, timeout=timeout)  # nosec B310\n           ^^^^^^^^^^^^^^^^^^^^^^^^^^^^^^^^^^^^^\n  File \"/usr/lib/python3.12/urllib/request.py\", line 215, in urlopen\n    return opener.open(url, data, timeout)\n           ^^^^^^^^^^^^^^^^^^^^^^^^^^^^^^^\n  File \"/usr/lib/python3.12/urllib/request.py\", line 515, in open\n    response = self._open(req, data)\n               ^^^^^^^^^^^^^^^^^^^^^\n  File \"/usr/lib/python3.12/urllib/request.py\", line 532, in _open\n    result = self._call_chain(self.handle_open, protocol, protocol +\n             ^^^^^^^^^^^^^^^^^^^^^^^^^^^^^^^^^^^^^^^^^^^^^^^^^^^^^^^\n  File \"/usr/lib/python3.12/urllib/request.py\", line 492, in _call_chain\n    result = func(*args)\n             ^^^^^^^^^^^\n  File \"/usr/lib/python3.12/urllib/request.py\", line 1392, in https_open\n    return self.do_open(http.client.HTTPSConnection, req,\n           ^^^^^^^^^^^^^^^^^^^^^^^^^^^^^^^^^^^^^^^^^^^^^^\n  File \"/usr/lib/python3.12/urllib/request.py\", line 1347, in do_open\n    raise URLError(err)\nurllib.error.URLError: <urlopen error [Errno 111] Connection refused>"}]
2025-05-21T13:03:51+00:00 liaserver2 python3[1483]: ["2025-05-21T13:03:51.096", "ERROR", "ubuntupro.lib.esm_cache", "main", 17, "Error updating the cache: Failed to connect to https://contracts.canonical.com/v1/resources?architecture=amd64&kernel=6.8.0-53-generic&series=noble&virt=oracle\n[Errno 111] Connection refused\n", {}]
2025-05-21T13:10:08+00:00 liaserver2 python3[1947]: ["2025-05-21T13:10:08.383", "ERROR", "ubuntupro.http", "_readurl_urllib", 171, "[Errno 111] Connection refused", {"exc_info": "Traceback (most recent call last):\n  File \"/usr/lib/python3.12/urllib/request.py\", line 1344, in do_open\n    h.request(req.get_method(), req.selector, req.data, headers,\n  File \"/usr/lib/python3.12/http/client.py\", line 1336, in request\n    self._send_request(method, url, body, headers, encode_chunked)\n  File \"/usr/lib/python3.12/http/client.py\", line 1382, in _send_request\n    self.endheaders(body, encode_chunked=encode_chunked)\n  File \"/usr/lib/python3.12/http/client.py\", line 1331, in endheaders\n    self._send_output(message_body, encode_chunked=encode_chunked)\n  File \"/usr/lib/python3.12/http/client.py\", line 1091, in _send_output\n    self.send(msg)\n  File \"/usr/lib/python3.12/http/client.py\", line 1035, in send\n    self.connect()\n  File \"/usr/lib/python3.12/http/client.py\", line 1470, in connect\n    super().connect()\n  File \"/usr/lib/python3.12/http/client.py\", line 1001, in connect\n    self.sock = self._create_connection(\n                ^^^^^^^^^^^^^^^^^^^^^^^^\n  File \"/usr/lib/python3.12/socket.py\", line 852, in create_connection\n    raise exceptions[0]\n  File \"/usr/lib/python3.12/socket.py\", line 837, in create_connection\n    sock.connect(sa)\nConnectionRefusedError: [Errno 111] Connection refused\n\nDuring handling of the above exception, another exception occurred:\n\nTraceback (most recent call last):\n  File \"/usr/lib/python3/dist-packages/uaclient/http/__init__.py\", line 167, in _readurl_urllib\n    resp = request.urlopen(req, timeout=timeout)  # nosec B310\n           ^^^^^^^^^^^^^^^^^^^^^^^^^^^^^^^^^^^^^\n  File \"/usr/lib/python3.12/urllib/request.py\", line 215, in urlopen\n    return opener.open(url, data, timeout)\n           ^^^^^^^^^^^^^^^^^^^^^^^^^^^^^^^\n  File \"/usr/lib/python3.12/urllib/request.py\", line 515, in open\n    response = self._open(req, data)\n               ^^^^^^^^^^^^^^^^^^^^^\n  File \"/usr/lib/python3.12/urllib/request.py\", line 532, in _open\n    result = self._call_chain(self.handle_open, protocol, protocol +\n             ^^^^^^^^^^^^^^^^^^^^^^^^^^^^^^^^^^^^^^^^^^^^^^^^^^^^^^^\n  File \"/usr/lib/python3.12/urllib/request.py\", line 492, in _call_chain\n    result = func(*args)\n             ^^^^^^^^^^^\n  File \"/usr/lib/python3.12/urllib/request.py\", line 1392, in https_open\n    return self.do_open(http.client.HTTPSConnection, req,\n           ^^^^^^^^^^^^^^^^^^^^^^^^^^^^^^^^^^^^^^^^^^^^^^\n  File \"/usr/lib/python3.12/urllib/request.py\", line 1347, in do_open\n    raise URLError(err)\nurllib.error.URLError: <urlopen error [Errno 111] Connection refused>"}]
2025-05-21T13:10:08+00:00 liaserver2 python3[1947]: ["2025-05-21T13:10:08.391", "ERROR", "ubuntupro.lib.esm_cache", "main", 17, "Error updating the cache: Failed to connect to https://contracts.canonical.com/v1/resources?architecture=amd64&kernel=6.8.0-53-generic&series=noble&virt=oracle\n[Errno 111] Connection refused\n", {}]
2025-05-21T13:19:17+00:00 liaserver2 python3[2027]: ["2025-05-21T13:19:17.601", "ERROR", "ubuntupro.http", "_readurl_urllib", 171, "[Errno 111] Connection refused", {"exc_info": "Traceback (most recent call last):\n  File \"/usr/lib/python3.12/urllib/request.py\", line 1344, in do_open\n    h.request(req.get_method(), req.selector, req.data, headers,\n  File \"/usr/lib/python3.12/http/client.py\", line 1336, in request\n    self._send_request(method, url, body, headers, encode_chunked)\n  File \"/usr/lib/python3.12/http/client.py\", line 1382, in _send_request\n    self.endheaders(body, encode_chunked=encode_chunked)\n  File \"/usr/lib/python3.12/http/client.py\", line 1331, in endheaders\n    self._send_output(message_body, encode_chunked=encode_chunked)\n  File \"/usr/lib/python3.12/http/client.py\", line 1091, in _send_output\n    self.send(msg)\n  File \"/usr/lib/python3.12/http/client.py\", line 1035, in send\n    self.connect()\n  File \"/usr/lib/python3.12/http/client.py\", line 1470, in connect\n    super().connect()\n  File \"/usr/lib/python3.12/http/client.py\", line 1001, in connect\n    self.sock = self._create_connection(\n                ^^^^^^^^^^^^^^^^^^^^^^^^\n  File \"/usr/lib/python3.12/socket.py\", line 852, in create_connection\n    raise exceptions[0]\n  File \"/usr/lib/python3.12/socket.py\", line 837, in create_connection\n    sock.connect(sa)\nConnectionRefusedError: [Errno 111] Connection refused\n\nDuring handling of the above exception, another exception occurred:\n\nTraceback (most recent call last):\n  File \"/usr/lib/python3/dist-packages/uaclient/http/__init__.py\", line 167, in _readurl_urllib\n    resp = request.urlopen(req, timeout=timeout)  # nosec B310\n           ^^^^^^^^^^^^^^^^^^^^^^^^^^^^^^^^^^^^^\n  File \"/usr/lib/python3.12/urllib/request.py\", line 215, in urlopen\n    return opener.open(url, data, timeout)\n           ^^^^^^^^^^^^^^^^^^^^^^^^^^^^^^^\n  File \"/usr/lib/python3.12/urllib/request.py\", line 515, in open\n    response = self._open(req, data)\n               ^^^^^^^^^^^^^^^^^^^^^\n  File \"/usr/lib/python3.12/urllib/request.py\", line 532, in _open\n    result = self._call_chain(self.handle_open, protocol, protocol +\n             ^^^^^^^^^^^^^^^^^^^^^^^^^^^^^^^^^^^^^^^^^^^^^^^^^^^^^^^\n  File \"/usr/lib/python3.12/urllib/request.py\", line 492, in _call_chain\n    result = func(*args)\n             ^^^^^^^^^^^\n  File \"/usr/lib/python3.12/urllib/request.py\", line 1392, in https_open\n    return self.do_open(http.client.HTTPSConnection, req,\n           ^^^^^^^^^^^^^^^^^^^^^^^^^^^^^^^^^^^^^^^^^^^^^^\n  File \"/usr/lib/python3.12/urllib/request.py\", line 1347, in do_open\n    raise URLError(err)\nurllib.error.URLError: <urlopen error [Errno 111] Connection refused>"}]
2025-05-21T13:19:17+00:00 liaserver2 python3[2027]: ["2025-05-21T13:19:17.608", "ERROR", "ubuntupro.lib.esm_cache", "main", 17, "Error updating the cache: Failed to connect to https://contracts.canonical.com/v1/resources?architecture=amd64&kernel=6.8.0-53-generic&series=noble&virt=oracle\n[Errno 111] Connection refused\n", {}]
2025-05-27T15:48:53+00:00 liaserver2 python3[35629]: /usr/lib/python3/dist-packages/uaclient/apt_news.py:207: Warning: W:Download is performed unsandboxed as root as file '/run/ubuntu-advantage/aptnews.json' couldn't be accessed by user '_apt'. - pkgAcquire::Run (13: Permission denied)
2025-05-27T15:48:53+00:00 liaserver2 python3[35629]:   acq.run()
2025-05-30T17:00:31+00:00 liaserver2 python3[1695]: /usr/lib/python3/dist-packages/uaclient/apt_news.py:207: Warning: W:Download is performed unsandboxed as root as file '/run/ubuntu-advantage/aptnews.json' couldn't be accessed by user '_apt'. - pkgAcquire::Run (13: Permission denied)
2025-05-30T17:00:31+00:00 liaserver2 python3[1695]:   acq.run()
